2021-04-06 22:12:32,468 -  nornir.core -     INFO -        run() - Running task 'load_vars' with args {} on 5 hosts
2021-04-06 22:12:32,495 - nornir.core.task -    ERROR -      start() - Host 'IOS4': task 'VLAN Commands' failed with traceback:
Traceback (most recent call last):
  File "/home/sunil/.local/lib/python3.8/site-packages/netmiko/base_connection.py", line 920, in establish_connection
    self.remote_conn_pre.connect(**ssh_connect_params)
  File "/usr/lib/python3/dist-packages/paramiko/client.py", line 368, in connect
    raise NoValidConnectionsError(errors)
paramiko.ssh_exception.NoValidConnectionsError: [Errno None] Unable to connect to port 22 on 192.168.127.44

During handling of the above exception, another exception occurred:

Traceback (most recent call last):
  File "/home/sunil/.local/lib/python3.8/site-packages/nornir/core/task.py", line 98, in start
    r = self.task(self, **self.params)
  File "/home/sunil/.local/lib/python3.8/site-packages/nornir_netmiko/tasks/netmiko_send_config.py", line 24, in netmiko_send_config
    net_connect = task.host.get_connection(CONNECTION_NAME, task.nornir.config)
  File "/home/sunil/.local/lib/python3.8/site-packages/nornir/core/inventory.py", line 440, in get_connection
    self.open_connection(
  File "/home/sunil/.local/lib/python3.8/site-packages/nornir/core/inventory.py", line 492, in open_connection
    conn_obj.open(
  File "/home/sunil/.local/lib/python3.8/site-packages/nornir_netmiko/connections/netmiko.py", line 59, in open
    connection = ConnectHandler(**parameters)
  File "/home/sunil/.local/lib/python3.8/site-packages/netmiko/ssh_dispatcher.py", line 312, in ConnectHandler
    return ConnectionClass(*args, **kwargs)
  File "/home/sunil/.local/lib/python3.8/site-packages/netmiko/cisco/cisco_ios.py", line 17, in __init__
    return super().__init__(*args, **kwargs)
  File "/home/sunil/.local/lib/python3.8/site-packages/netmiko/base_connection.py", line 346, in __init__
    self._open()
  File "/home/sunil/.local/lib/python3.8/site-packages/netmiko/base_connection.py", line 351, in _open
    self.establish_connection()
  File "/home/sunil/.local/lib/python3.8/site-packages/netmiko/base_connection.py", line 942, in establish_connection
    raise NetmikoTimeoutException(msg)
netmiko.ssh_exception.NetmikoTimeoutException: TCP connection to device failed.

Common causes of this problem are:
1. Incorrect hostname or IP address.
2. Wrong TCP port.
3. Intermediate firewall blocking access.

Device settings: cisco_ios 192.168.127.44:22



2021-04-06 22:12:32,495 - nornir.core.task -    ERROR -      start() - Host 'IOS4': task 'load_vars' failed with traceback:
Traceback (most recent call last):
  File "/home/sunil/.local/lib/python3.8/site-packages/nornir/core/task.py", line 98, in start
    r = self.task(self, **self.params)
  File "test2-IMP.py", line 82, in load_vars
    basic_configuration(task1)
  File "test2-IMP.py", line 91, in basic_configuration
    task1.run(task=netmiko_send_config, name="VLAN Commands",
  File "/home/sunil/.local/lib/python3.8/site-packages/nornir/core/task.py", line 168, in run
    raise NornirSubTaskError(task=run_task, result=r)
nornir.core.exceptions.NornirSubTaskError: Subtask: VLAN Commands (failed)


2021-04-06 22:12:35,549 - nornir.core.task -    ERROR -      start() - Host 'IOS2': task 'VLAN Commands' failed with traceback:
Traceback (most recent call last):
  File "/home/sunil/.local/lib/python3.8/site-packages/netmiko/base_connection.py", line 920, in establish_connection
    self.remote_conn_pre.connect(**ssh_connect_params)
  File "/usr/lib/python3/dist-packages/paramiko/client.py", line 368, in connect
    raise NoValidConnectionsError(errors)
paramiko.ssh_exception.NoValidConnectionsError: [Errno None] Unable to connect to port 22 on 192.168.127.42

During handling of the above exception, another exception occurred:

Traceback (most recent call last):
  File "/home/sunil/.local/lib/python3.8/site-packages/nornir/core/task.py", line 98, in start
    r = self.task(self, **self.params)
  File "/home/sunil/.local/lib/python3.8/site-packages/nornir_netmiko/tasks/netmiko_send_config.py", line 24, in netmiko_send_config
    net_connect = task.host.get_connection(CONNECTION_NAME, task.nornir.config)
  File "/home/sunil/.local/lib/python3.8/site-packages/nornir/core/inventory.py", line 440, in get_connection
    self.open_connection(
  File "/home/sunil/.local/lib/python3.8/site-packages/nornir/core/inventory.py", line 492, in open_connection
    conn_obj.open(
  File "/home/sunil/.local/lib/python3.8/site-packages/nornir_netmiko/connections/netmiko.py", line 59, in open
    connection = ConnectHandler(**parameters)
  File "/home/sunil/.local/lib/python3.8/site-packages/netmiko/ssh_dispatcher.py", line 312, in ConnectHandler
    return ConnectionClass(*args, **kwargs)
  File "/home/sunil/.local/lib/python3.8/site-packages/netmiko/cisco/cisco_ios.py", line 17, in __init__
    return super().__init__(*args, **kwargs)
  File "/home/sunil/.local/lib/python3.8/site-packages/netmiko/base_connection.py", line 346, in __init__
    self._open()
  File "/home/sunil/.local/lib/python3.8/site-packages/netmiko/base_connection.py", line 351, in _open
    self.establish_connection()
  File "/home/sunil/.local/lib/python3.8/site-packages/netmiko/base_connection.py", line 942, in establish_connection
    raise NetmikoTimeoutException(msg)
netmiko.ssh_exception.NetmikoTimeoutException: TCP connection to device failed.

Common causes of this problem are:
1. Incorrect hostname or IP address.
2. Wrong TCP port.
3. Intermediate firewall blocking access.

Device settings: cisco_ios 192.168.127.42:22



2021-04-06 22:12:35,550 - nornir.core.task -    ERROR -      start() - Host 'IOS2': task 'load_vars' failed with traceback:
Traceback (most recent call last):
  File "/home/sunil/.local/lib/python3.8/site-packages/nornir/core/task.py", line 98, in start
    r = self.task(self, **self.params)
  File "test2-IMP.py", line 82, in load_vars
    basic_configuration(task1)
  File "test2-IMP.py", line 91, in basic_configuration
    task1.run(task=netmiko_send_config, name="VLAN Commands",
  File "/home/sunil/.local/lib/python3.8/site-packages/nornir/core/task.py", line 168, in run
    raise NornirSubTaskError(task=run_task, result=r)
nornir.core.exceptions.NornirSubTaskError: Subtask: VLAN Commands (failed)


2021-04-06 22:12:35,549 - nornir.core.task -    ERROR -      start() - Host 'leaf1': task 'VLAN Commands' failed with traceback:
Traceback (most recent call last):
  File "/home/sunil/.local/lib/python3.8/site-packages/netmiko/base_connection.py", line 920, in establish_connection
    self.remote_conn_pre.connect(**ssh_connect_params)
  File "/usr/lib/python3/dist-packages/paramiko/client.py", line 368, in connect
    raise NoValidConnectionsError(errors)
paramiko.ssh_exception.NoValidConnectionsError: [Errno None] Unable to connect to port 22 on 192.168.127.12

During handling of the above exception, another exception occurred:

Traceback (most recent call last):
  File "/home/sunil/.local/lib/python3.8/site-packages/nornir/core/task.py", line 98, in start
    r = self.task(self, **self.params)
  File "/home/sunil/.local/lib/python3.8/site-packages/nornir_netmiko/tasks/netmiko_send_config.py", line 24, in netmiko_send_config
    net_connect = task.host.get_connection(CONNECTION_NAME, task.nornir.config)
  File "/home/sunil/.local/lib/python3.8/site-packages/nornir/core/inventory.py", line 440, in get_connection
    self.open_connection(
  File "/home/sunil/.local/lib/python3.8/site-packages/nornir/core/inventory.py", line 492, in open_connection
    conn_obj.open(
  File "/home/sunil/.local/lib/python3.8/site-packages/nornir_netmiko/connections/netmiko.py", line 59, in open
    connection = ConnectHandler(**parameters)
  File "/home/sunil/.local/lib/python3.8/site-packages/netmiko/ssh_dispatcher.py", line 312, in ConnectHandler
    return ConnectionClass(*args, **kwargs)
  File "/home/sunil/.local/lib/python3.8/site-packages/netmiko/cisco/cisco_nxos_ssh.py", line 12, in __init__
    return super().__init__(*args, **kwargs)
  File "/home/sunil/.local/lib/python3.8/site-packages/netmiko/base_connection.py", line 346, in __init__
    self._open()
  File "/home/sunil/.local/lib/python3.8/site-packages/netmiko/base_connection.py", line 351, in _open
    self.establish_connection()
  File "/home/sunil/.local/lib/python3.8/site-packages/netmiko/base_connection.py", line 942, in establish_connection
    raise NetmikoTimeoutException(msg)
netmiko.ssh_exception.NetmikoTimeoutException: TCP connection to device failed.

Common causes of this problem are:
1. Incorrect hostname or IP address.
2. Wrong TCP port.
3. Intermediate firewall blocking access.

Device settings: cisco_nxos 192.168.127.12:22



2021-04-06 22:12:35,550 - nornir.core.task -    ERROR -      start() - Host 'leaf1': task 'load_vars' failed with traceback:
Traceback (most recent call last):
  File "/home/sunil/.local/lib/python3.8/site-packages/nornir/core/task.py", line 98, in start
    r = self.task(self, **self.params)
  File "test2-IMP.py", line 82, in load_vars
    basic_configuration(task1)
  File "test2-IMP.py", line 91, in basic_configuration
    task1.run(task=netmiko_send_config, name="VLAN Commands",
  File "/home/sunil/.local/lib/python3.8/site-packages/nornir/core/task.py", line 168, in run
    raise NornirSubTaskError(task=run_task, result=r)
nornir.core.exceptions.NornirSubTaskError: Subtask: VLAN Commands (failed)


2021-04-06 22:12:35,553 - nornir.core.task -    ERROR -      start() - Host 'spine1': task 'VLAN Commands' failed with traceback:
Traceback (most recent call last):
  File "/home/sunil/.local/lib/python3.8/site-packages/netmiko/base_connection.py", line 920, in establish_connection
    self.remote_conn_pre.connect(**ssh_connect_params)
  File "/usr/lib/python3/dist-packages/paramiko/client.py", line 368, in connect
    raise NoValidConnectionsError(errors)
paramiko.ssh_exception.NoValidConnectionsError: [Errno None] Unable to connect to port 22 on 192.168.127.11

During handling of the above exception, another exception occurred:

Traceback (most recent call last):
  File "/home/sunil/.local/lib/python3.8/site-packages/nornir/core/task.py", line 98, in start
    r = self.task(self, **self.params)
  File "/home/sunil/.local/lib/python3.8/site-packages/nornir_netmiko/tasks/netmiko_send_config.py", line 24, in netmiko_send_config
    net_connect = task.host.get_connection(CONNECTION_NAME, task.nornir.config)
  File "/home/sunil/.local/lib/python3.8/site-packages/nornir/core/inventory.py", line 440, in get_connection
    self.open_connection(
  File "/home/sunil/.local/lib/python3.8/site-packages/nornir/core/inventory.py", line 492, in open_connection
    conn_obj.open(
  File "/home/sunil/.local/lib/python3.8/site-packages/nornir_netmiko/connections/netmiko.py", line 59, in open
    connection = ConnectHandler(**parameters)
  File "/home/sunil/.local/lib/python3.8/site-packages/netmiko/ssh_dispatcher.py", line 312, in ConnectHandler
    return ConnectionClass(*args, **kwargs)
  File "/home/sunil/.local/lib/python3.8/site-packages/netmiko/cisco/cisco_nxos_ssh.py", line 12, in __init__
    return super().__init__(*args, **kwargs)
  File "/home/sunil/.local/lib/python3.8/site-packages/netmiko/base_connection.py", line 346, in __init__
    self._open()
  File "/home/sunil/.local/lib/python3.8/site-packages/netmiko/base_connection.py", line 351, in _open
    self.establish_connection()
  File "/home/sunil/.local/lib/python3.8/site-packages/netmiko/base_connection.py", line 942, in establish_connection
    raise NetmikoTimeoutException(msg)
netmiko.ssh_exception.NetmikoTimeoutException: TCP connection to device failed.

Common causes of this problem are:
1. Incorrect hostname or IP address.
2. Wrong TCP port.
3. Intermediate firewall blocking access.

Device settings: cisco_nxos 192.168.127.11:22



2021-04-06 22:12:35,553 - nornir.core.task -    ERROR -      start() - Host 'spine1': task 'load_vars' failed with traceback:
Traceback (most recent call last):
  File "/home/sunil/.local/lib/python3.8/site-packages/nornir/core/task.py", line 98, in start
    r = self.task(self, **self.params)
  File "test2-IMP.py", line 82, in load_vars
    basic_configuration(task1)
  File "test2-IMP.py", line 91, in basic_configuration
    task1.run(task=netmiko_send_config, name="VLAN Commands",
  File "/home/sunil/.local/lib/python3.8/site-packages/nornir/core/task.py", line 168, in run
    raise NornirSubTaskError(task=run_task, result=r)
nornir.core.exceptions.NornirSubTaskError: Subtask: VLAN Commands (failed)


2021-04-06 22:12:35,554 - nornir.core.task -    ERROR -      start() - Host 'IOS3': task 'VLAN Commands' failed with traceback:
Traceback (most recent call last):
  File "/home/sunil/.local/lib/python3.8/site-packages/netmiko/base_connection.py", line 920, in establish_connection
    self.remote_conn_pre.connect(**ssh_connect_params)
  File "/usr/lib/python3/dist-packages/paramiko/client.py", line 368, in connect
    raise NoValidConnectionsError(errors)
paramiko.ssh_exception.NoValidConnectionsError: [Errno None] Unable to connect to port 22 on 192.168.127.43

During handling of the above exception, another exception occurred:

Traceback (most recent call last):
  File "/home/sunil/.local/lib/python3.8/site-packages/nornir/core/task.py", line 98, in start
    r = self.task(self, **self.params)
  File "/home/sunil/.local/lib/python3.8/site-packages/nornir_netmiko/tasks/netmiko_send_config.py", line 24, in netmiko_send_config
    net_connect = task.host.get_connection(CONNECTION_NAME, task.nornir.config)
  File "/home/sunil/.local/lib/python3.8/site-packages/nornir/core/inventory.py", line 440, in get_connection
    self.open_connection(
  File "/home/sunil/.local/lib/python3.8/site-packages/nornir/core/inventory.py", line 492, in open_connection
    conn_obj.open(
  File "/home/sunil/.local/lib/python3.8/site-packages/nornir_netmiko/connections/netmiko.py", line 59, in open
    connection = ConnectHandler(**parameters)
  File "/home/sunil/.local/lib/python3.8/site-packages/netmiko/ssh_dispatcher.py", line 312, in ConnectHandler
    return ConnectionClass(*args, **kwargs)
  File "/home/sunil/.local/lib/python3.8/site-packages/netmiko/cisco/cisco_ios.py", line 17, in __init__
    return super().__init__(*args, **kwargs)
  File "/home/sunil/.local/lib/python3.8/site-packages/netmiko/base_connection.py", line 346, in __init__
    self._open()
  File "/home/sunil/.local/lib/python3.8/site-packages/netmiko/base_connection.py", line 351, in _open
    self.establish_connection()
  File "/home/sunil/.local/lib/python3.8/site-packages/netmiko/base_connection.py", line 942, in establish_connection
    raise NetmikoTimeoutException(msg)
netmiko.ssh_exception.NetmikoTimeoutException: TCP connection to device failed.

Common causes of this problem are:
1. Incorrect hostname or IP address.
2. Wrong TCP port.
3. Intermediate firewall blocking access.

Device settings: cisco_ios 192.168.127.43:22



2021-04-06 22:12:35,554 - nornir.core.task -    ERROR -      start() - Host 'IOS3': task 'load_vars' failed with traceback:
Traceback (most recent call last):
  File "/home/sunil/.local/lib/python3.8/site-packages/nornir/core/task.py", line 98, in start
    r = self.task(self, **self.params)
  File "test2-IMP.py", line 82, in load_vars
    basic_configuration(task1)
  File "test2-IMP.py", line 91, in basic_configuration
    task1.run(task=netmiko_send_config, name="VLAN Commands",
  File "/home/sunil/.local/lib/python3.8/site-packages/nornir/core/task.py", line 168, in run
    raise NornirSubTaskError(task=run_task, result=r)
nornir.core.exceptions.NornirSubTaskError: Subtask: VLAN Commands (failed)


2021-04-06 22:23:34,761 -  nornir.core -     INFO -        run() - Running task 'load_vars' with args {} on 5 hosts
2021-04-06 22:23:34,784 - nornir.core.task -    ERROR -      start() - Host 'IOS4': task 'VLAN Commands' failed with traceback:
Traceback (most recent call last):
  File "/home/sunil/.local/lib/python3.8/site-packages/netmiko/base_connection.py", line 920, in establish_connection
    self.remote_conn_pre.connect(**ssh_connect_params)
  File "/usr/lib/python3/dist-packages/paramiko/client.py", line 368, in connect
    raise NoValidConnectionsError(errors)
paramiko.ssh_exception.NoValidConnectionsError: [Errno None] Unable to connect to port 22 on 192.168.127.44

During handling of the above exception, another exception occurred:

Traceback (most recent call last):
  File "/home/sunil/.local/lib/python3.8/site-packages/nornir/core/task.py", line 98, in start
    r = self.task(self, **self.params)
  File "/home/sunil/.local/lib/python3.8/site-packages/nornir_netmiko/tasks/netmiko_send_config.py", line 24, in netmiko_send_config
    net_connect = task.host.get_connection(CONNECTION_NAME, task.nornir.config)
  File "/home/sunil/.local/lib/python3.8/site-packages/nornir/core/inventory.py", line 440, in get_connection
    self.open_connection(
  File "/home/sunil/.local/lib/python3.8/site-packages/nornir/core/inventory.py", line 492, in open_connection
    conn_obj.open(
  File "/home/sunil/.local/lib/python3.8/site-packages/nornir_netmiko/connections/netmiko.py", line 59, in open
    connection = ConnectHandler(**parameters)
  File "/home/sunil/.local/lib/python3.8/site-packages/netmiko/ssh_dispatcher.py", line 312, in ConnectHandler
    return ConnectionClass(*args, **kwargs)
  File "/home/sunil/.local/lib/python3.8/site-packages/netmiko/cisco/cisco_ios.py", line 17, in __init__
    return super().__init__(*args, **kwargs)
  File "/home/sunil/.local/lib/python3.8/site-packages/netmiko/base_connection.py", line 346, in __init__
    self._open()
  File "/home/sunil/.local/lib/python3.8/site-packages/netmiko/base_connection.py", line 351, in _open
    self.establish_connection()
  File "/home/sunil/.local/lib/python3.8/site-packages/netmiko/base_connection.py", line 942, in establish_connection
    raise NetmikoTimeoutException(msg)
netmiko.ssh_exception.NetmikoTimeoutException: TCP connection to device failed.

Common causes of this problem are:
1. Incorrect hostname or IP address.
2. Wrong TCP port.
3. Intermediate firewall blocking access.

Device settings: cisco_ios 192.168.127.44:22



2021-04-06 22:23:34,785 - nornir.core.task -    ERROR -      start() - Host 'IOS4': task 'load_vars' failed with traceback:
Traceback (most recent call last):
  File "/home/sunil/.local/lib/python3.8/site-packages/nornir/core/task.py", line 98, in start
    r = self.task(self, **self.params)
  File "test2-IMP-1.py", line 82, in load_vars
    basic_configuration(task1)
  File "test2-IMP-1.py", line 91, in basic_configuration
    task1.run(task=netmiko_send_config, name="VLAN Commands",
  File "/home/sunil/.local/lib/python3.8/site-packages/nornir/core/task.py", line 168, in run
    raise NornirSubTaskError(task=run_task, result=r)
nornir.core.exceptions.NornirSubTaskError: Subtask: VLAN Commands (failed)


2021-04-06 22:23:37,821 - nornir.core.task -    ERROR -      start() - Host 'leaf1': task 'VLAN Commands' failed with traceback:
Traceback (most recent call last):
  File "/home/sunil/.local/lib/python3.8/site-packages/netmiko/base_connection.py", line 920, in establish_connection
    self.remote_conn_pre.connect(**ssh_connect_params)
  File "/usr/lib/python3/dist-packages/paramiko/client.py", line 368, in connect
    raise NoValidConnectionsError(errors)
paramiko.ssh_exception.NoValidConnectionsError: [Errno None] Unable to connect to port 22 on 192.168.127.12

During handling of the above exception, another exception occurred:

Traceback (most recent call last):
  File "/home/sunil/.local/lib/python3.8/site-packages/nornir/core/task.py", line 98, in start
    r = self.task(self, **self.params)
  File "/home/sunil/.local/lib/python3.8/site-packages/nornir_netmiko/tasks/netmiko_send_config.py", line 24, in netmiko_send_config
    net_connect = task.host.get_connection(CONNECTION_NAME, task.nornir.config)
  File "/home/sunil/.local/lib/python3.8/site-packages/nornir/core/inventory.py", line 440, in get_connection
    self.open_connection(
  File "/home/sunil/.local/lib/python3.8/site-packages/nornir/core/inventory.py", line 492, in open_connection
    conn_obj.open(
  File "/home/sunil/.local/lib/python3.8/site-packages/nornir_netmiko/connections/netmiko.py", line 59, in open
    connection = ConnectHandler(**parameters)
  File "/home/sunil/.local/lib/python3.8/site-packages/netmiko/ssh_dispatcher.py", line 312, in ConnectHandler
    return ConnectionClass(*args, **kwargs)
  File "/home/sunil/.local/lib/python3.8/site-packages/netmiko/cisco/cisco_nxos_ssh.py", line 12, in __init__
    return super().__init__(*args, **kwargs)
  File "/home/sunil/.local/lib/python3.8/site-packages/netmiko/base_connection.py", line 346, in __init__
    self._open()
  File "/home/sunil/.local/lib/python3.8/site-packages/netmiko/base_connection.py", line 351, in _open
    self.establish_connection()
  File "/home/sunil/.local/lib/python3.8/site-packages/netmiko/base_connection.py", line 942, in establish_connection
    raise NetmikoTimeoutException(msg)
netmiko.ssh_exception.NetmikoTimeoutException: TCP connection to device failed.

Common causes of this problem are:
1. Incorrect hostname or IP address.
2. Wrong TCP port.
3. Intermediate firewall blocking access.

Device settings: cisco_nxos 192.168.127.12:22



2021-04-06 22:23:37,821 - nornir.core.task -    ERROR -      start() - Host 'leaf1': task 'load_vars' failed with traceback:
Traceback (most recent call last):
  File "/home/sunil/.local/lib/python3.8/site-packages/nornir/core/task.py", line 98, in start
    r = self.task(self, **self.params)
  File "test2-IMP-1.py", line 82, in load_vars
    basic_configuration(task1)
  File "test2-IMP-1.py", line 91, in basic_configuration
    task1.run(task=netmiko_send_config, name="VLAN Commands",
  File "/home/sunil/.local/lib/python3.8/site-packages/nornir/core/task.py", line 168, in run
    raise NornirSubTaskError(task=run_task, result=r)
nornir.core.exceptions.NornirSubTaskError: Subtask: VLAN Commands (failed)


2021-04-06 22:23:37,852 - nornir.core.task -    ERROR -      start() - Host 'IOS3': task 'VLAN Commands' failed with traceback:
Traceback (most recent call last):
  File "/home/sunil/.local/lib/python3.8/site-packages/netmiko/base_connection.py", line 920, in establish_connection
    self.remote_conn_pre.connect(**ssh_connect_params)
  File "/usr/lib/python3/dist-packages/paramiko/client.py", line 368, in connect
    raise NoValidConnectionsError(errors)
paramiko.ssh_exception.NoValidConnectionsError: [Errno None] Unable to connect to port 22 on 192.168.127.43

During handling of the above exception, another exception occurred:

Traceback (most recent call last):
  File "/home/sunil/.local/lib/python3.8/site-packages/nornir/core/task.py", line 98, in start
    r = self.task(self, **self.params)
  File "/home/sunil/.local/lib/python3.8/site-packages/nornir_netmiko/tasks/netmiko_send_config.py", line 24, in netmiko_send_config
    net_connect = task.host.get_connection(CONNECTION_NAME, task.nornir.config)
  File "/home/sunil/.local/lib/python3.8/site-packages/nornir/core/inventory.py", line 440, in get_connection
    self.open_connection(
  File "/home/sunil/.local/lib/python3.8/site-packages/nornir/core/inventory.py", line 492, in open_connection
    conn_obj.open(
  File "/home/sunil/.local/lib/python3.8/site-packages/nornir_netmiko/connections/netmiko.py", line 59, in open
    connection = ConnectHandler(**parameters)
  File "/home/sunil/.local/lib/python3.8/site-packages/netmiko/ssh_dispatcher.py", line 312, in ConnectHandler
    return ConnectionClass(*args, **kwargs)
  File "/home/sunil/.local/lib/python3.8/site-packages/netmiko/cisco/cisco_ios.py", line 17, in __init__
    return super().__init__(*args, **kwargs)
  File "/home/sunil/.local/lib/python3.8/site-packages/netmiko/base_connection.py", line 346, in __init__
    self._open()
  File "/home/sunil/.local/lib/python3.8/site-packages/netmiko/base_connection.py", line 351, in _open
    self.establish_connection()
  File "/home/sunil/.local/lib/python3.8/site-packages/netmiko/base_connection.py", line 942, in establish_connection
    raise NetmikoTimeoutException(msg)
netmiko.ssh_exception.NetmikoTimeoutException: TCP connection to device failed.

Common causes of this problem are:
1. Incorrect hostname or IP address.
2. Wrong TCP port.
3. Intermediate firewall blocking access.

Device settings: cisco_ios 192.168.127.43:22



2021-04-06 22:23:37,852 - nornir.core.task -    ERROR -      start() - Host 'IOS3': task 'load_vars' failed with traceback:
Traceback (most recent call last):
  File "/home/sunil/.local/lib/python3.8/site-packages/nornir/core/task.py", line 98, in start
    r = self.task(self, **self.params)
  File "test2-IMP-1.py", line 82, in load_vars
    basic_configuration(task1)
  File "test2-IMP-1.py", line 91, in basic_configuration
    task1.run(task=netmiko_send_config, name="VLAN Commands",
  File "/home/sunil/.local/lib/python3.8/site-packages/nornir/core/task.py", line 168, in run
    raise NornirSubTaskError(task=run_task, result=r)
nornir.core.exceptions.NornirSubTaskError: Subtask: VLAN Commands (failed)


2021-04-06 22:23:37,853 - nornir.core.task -    ERROR -      start() - Host 'spine1': task 'VLAN Commands' failed with traceback:
Traceback (most recent call last):
  File "/home/sunil/.local/lib/python3.8/site-packages/netmiko/base_connection.py", line 920, in establish_connection
    self.remote_conn_pre.connect(**ssh_connect_params)
  File "/usr/lib/python3/dist-packages/paramiko/client.py", line 368, in connect
    raise NoValidConnectionsError(errors)
paramiko.ssh_exception.NoValidConnectionsError: [Errno None] Unable to connect to port 22 on 192.168.127.11

During handling of the above exception, another exception occurred:

Traceback (most recent call last):
  File "/home/sunil/.local/lib/python3.8/site-packages/nornir/core/task.py", line 98, in start
    r = self.task(self, **self.params)
  File "/home/sunil/.local/lib/python3.8/site-packages/nornir_netmiko/tasks/netmiko_send_config.py", line 24, in netmiko_send_config
    net_connect = task.host.get_connection(CONNECTION_NAME, task.nornir.config)
  File "/home/sunil/.local/lib/python3.8/site-packages/nornir/core/inventory.py", line 440, in get_connection
    self.open_connection(
  File "/home/sunil/.local/lib/python3.8/site-packages/nornir/core/inventory.py", line 492, in open_connection
    conn_obj.open(
  File "/home/sunil/.local/lib/python3.8/site-packages/nornir_netmiko/connections/netmiko.py", line 59, in open
    connection = ConnectHandler(**parameters)
  File "/home/sunil/.local/lib/python3.8/site-packages/netmiko/ssh_dispatcher.py", line 312, in ConnectHandler
    return ConnectionClass(*args, **kwargs)
  File "/home/sunil/.local/lib/python3.8/site-packages/netmiko/cisco/cisco_nxos_ssh.py", line 12, in __init__
    return super().__init__(*args, **kwargs)
  File "/home/sunil/.local/lib/python3.8/site-packages/netmiko/base_connection.py", line 346, in __init__
    self._open()
  File "/home/sunil/.local/lib/python3.8/site-packages/netmiko/base_connection.py", line 351, in _open
    self.establish_connection()
  File "/home/sunil/.local/lib/python3.8/site-packages/netmiko/base_connection.py", line 942, in establish_connection
    raise NetmikoTimeoutException(msg)
netmiko.ssh_exception.NetmikoTimeoutException: TCP connection to device failed.

Common causes of this problem are:
1. Incorrect hostname or IP address.
2. Wrong TCP port.
3. Intermediate firewall blocking access.

Device settings: cisco_nxos 192.168.127.11:22



2021-04-06 22:23:37,853 - nornir.core.task -    ERROR -      start() - Host 'spine1': task 'load_vars' failed with traceback:
Traceback (most recent call last):
  File "/home/sunil/.local/lib/python3.8/site-packages/nornir/core/task.py", line 98, in start
    r = self.task(self, **self.params)
  File "test2-IMP-1.py", line 82, in load_vars
    basic_configuration(task1)
  File "test2-IMP-1.py", line 91, in basic_configuration
    task1.run(task=netmiko_send_config, name="VLAN Commands",
  File "/home/sunil/.local/lib/python3.8/site-packages/nornir/core/task.py", line 168, in run
    raise NornirSubTaskError(task=run_task, result=r)
nornir.core.exceptions.NornirSubTaskError: Subtask: VLAN Commands (failed)


2021-04-06 22:23:37,853 - nornir.core.task -    ERROR -      start() - Host 'IOS2': task 'VLAN Commands' failed with traceback:
Traceback (most recent call last):
  File "/home/sunil/.local/lib/python3.8/site-packages/netmiko/base_connection.py", line 920, in establish_connection
    self.remote_conn_pre.connect(**ssh_connect_params)
  File "/usr/lib/python3/dist-packages/paramiko/client.py", line 368, in connect
    raise NoValidConnectionsError(errors)
paramiko.ssh_exception.NoValidConnectionsError: [Errno None] Unable to connect to port 22 on 192.168.127.42

During handling of the above exception, another exception occurred:

Traceback (most recent call last):
  File "/home/sunil/.local/lib/python3.8/site-packages/nornir/core/task.py", line 98, in start
    r = self.task(self, **self.params)
  File "/home/sunil/.local/lib/python3.8/site-packages/nornir_netmiko/tasks/netmiko_send_config.py", line 24, in netmiko_send_config
    net_connect = task.host.get_connection(CONNECTION_NAME, task.nornir.config)
  File "/home/sunil/.local/lib/python3.8/site-packages/nornir/core/inventory.py", line 440, in get_connection
    self.open_connection(
  File "/home/sunil/.local/lib/python3.8/site-packages/nornir/core/inventory.py", line 492, in open_connection
    conn_obj.open(
  File "/home/sunil/.local/lib/python3.8/site-packages/nornir_netmiko/connections/netmiko.py", line 59, in open
    connection = ConnectHandler(**parameters)
  File "/home/sunil/.local/lib/python3.8/site-packages/netmiko/ssh_dispatcher.py", line 312, in ConnectHandler
    return ConnectionClass(*args, **kwargs)
  File "/home/sunil/.local/lib/python3.8/site-packages/netmiko/cisco/cisco_ios.py", line 17, in __init__
    return super().__init__(*args, **kwargs)
  File "/home/sunil/.local/lib/python3.8/site-packages/netmiko/base_connection.py", line 346, in __init__
    self._open()
  File "/home/sunil/.local/lib/python3.8/site-packages/netmiko/base_connection.py", line 351, in _open
    self.establish_connection()
  File "/home/sunil/.local/lib/python3.8/site-packages/netmiko/base_connection.py", line 942, in establish_connection
    raise NetmikoTimeoutException(msg)
netmiko.ssh_exception.NetmikoTimeoutException: TCP connection to device failed.

Common causes of this problem are:
1. Incorrect hostname or IP address.
2. Wrong TCP port.
3. Intermediate firewall blocking access.

Device settings: cisco_ios 192.168.127.42:22



2021-04-06 22:23:37,854 - nornir.core.task -    ERROR -      start() - Host 'IOS2': task 'load_vars' failed with traceback:
Traceback (most recent call last):
  File "/home/sunil/.local/lib/python3.8/site-packages/nornir/core/task.py", line 98, in start
    r = self.task(self, **self.params)
  File "test2-IMP-1.py", line 82, in load_vars
    basic_configuration(task1)
  File "test2-IMP-1.py", line 91, in basic_configuration
    task1.run(task=netmiko_send_config, name="VLAN Commands",
  File "/home/sunil/.local/lib/python3.8/site-packages/nornir/core/task.py", line 168, in run
    raise NornirSubTaskError(task=run_task, result=r)
nornir.core.exceptions.NornirSubTaskError: Subtask: VLAN Commands (failed)


2021-04-07 17:29:11,424 -  nornir.core -     INFO -        run() - Running task 'load_vars' with args {} on 5 hosts
2021-04-07 17:29:11,448 - nornir.core.task -    ERROR -      start() - Host 'IOS4': task 'VLAN Commands' failed with traceback:
Traceback (most recent call last):
  File "/home/sunil/.local/lib/python3.8/site-packages/netmiko/base_connection.py", line 920, in establish_connection
    self.remote_conn_pre.connect(**ssh_connect_params)
  File "/usr/lib/python3/dist-packages/paramiko/client.py", line 368, in connect
    raise NoValidConnectionsError(errors)
paramiko.ssh_exception.NoValidConnectionsError: [Errno None] Unable to connect to port 22 on 192.168.127.44

During handling of the above exception, another exception occurred:

Traceback (most recent call last):
  File "/home/sunil/.local/lib/python3.8/site-packages/nornir/core/task.py", line 98, in start
    r = self.task(self, **self.params)
  File "/home/sunil/.local/lib/python3.8/site-packages/nornir_netmiko/tasks/netmiko_send_config.py", line 24, in netmiko_send_config
    net_connect = task.host.get_connection(CONNECTION_NAME, task.nornir.config)
  File "/home/sunil/.local/lib/python3.8/site-packages/nornir/core/inventory.py", line 440, in get_connection
    self.open_connection(
  File "/home/sunil/.local/lib/python3.8/site-packages/nornir/core/inventory.py", line 492, in open_connection
    conn_obj.open(
  File "/home/sunil/.local/lib/python3.8/site-packages/nornir_netmiko/connections/netmiko.py", line 59, in open
    connection = ConnectHandler(**parameters)
  File "/home/sunil/.local/lib/python3.8/site-packages/netmiko/ssh_dispatcher.py", line 312, in ConnectHandler
    return ConnectionClass(*args, **kwargs)
  File "/home/sunil/.local/lib/python3.8/site-packages/netmiko/cisco/cisco_ios.py", line 17, in __init__
    return super().__init__(*args, **kwargs)
  File "/home/sunil/.local/lib/python3.8/site-packages/netmiko/base_connection.py", line 346, in __init__
    self._open()
  File "/home/sunil/.local/lib/python3.8/site-packages/netmiko/base_connection.py", line 351, in _open
    self.establish_connection()
  File "/home/sunil/.local/lib/python3.8/site-packages/netmiko/base_connection.py", line 942, in establish_connection
    raise NetmikoTimeoutException(msg)
netmiko.ssh_exception.NetmikoTimeoutException: TCP connection to device failed.

Common causes of this problem are:
1. Incorrect hostname or IP address.
2. Wrong TCP port.
3. Intermediate firewall blocking access.

Device settings: cisco_ios 192.168.127.44:22



2021-04-07 17:29:11,450 - nornir.core.task -    ERROR -      start() - Host 'IOS4': task 'load_vars' failed with traceback:
Traceback (most recent call last):
  File "/home/sunil/.local/lib/python3.8/site-packages/nornir/core/task.py", line 98, in start
    r = self.task(self, **self.params)
  File "test-150.py", line 86, in load_vars
    basic_configuration(task1)
  File "test-150.py", line 95, in basic_configuration
    task1.run(task=netmiko_send_config, name="VLAN Commands",
  File "/home/sunil/.local/lib/python3.8/site-packages/nornir/core/task.py", line 168, in run
    raise NornirSubTaskError(task=run_task, result=r)
nornir.core.exceptions.NornirSubTaskError: Subtask: VLAN Commands (failed)


2021-04-07 17:29:14,494 - nornir.core.task -    ERROR -      start() - Host 'IOS2': task 'VLAN Commands' failed with traceback:
Traceback (most recent call last):
  File "/home/sunil/.local/lib/python3.8/site-packages/netmiko/base_connection.py", line 920, in establish_connection
    self.remote_conn_pre.connect(**ssh_connect_params)
  File "/usr/lib/python3/dist-packages/paramiko/client.py", line 368, in connect
    raise NoValidConnectionsError(errors)
paramiko.ssh_exception.NoValidConnectionsError: [Errno None] Unable to connect to port 22 on 192.168.127.42

During handling of the above exception, another exception occurred:

Traceback (most recent call last):
  File "/home/sunil/.local/lib/python3.8/site-packages/nornir/core/task.py", line 98, in start
    r = self.task(self, **self.params)
  File "/home/sunil/.local/lib/python3.8/site-packages/nornir_netmiko/tasks/netmiko_send_config.py", line 24, in netmiko_send_config
    net_connect = task.host.get_connection(CONNECTION_NAME, task.nornir.config)
  File "/home/sunil/.local/lib/python3.8/site-packages/nornir/core/inventory.py", line 440, in get_connection
    self.open_connection(
  File "/home/sunil/.local/lib/python3.8/site-packages/nornir/core/inventory.py", line 492, in open_connection
    conn_obj.open(
  File "/home/sunil/.local/lib/python3.8/site-packages/nornir_netmiko/connections/netmiko.py", line 59, in open
    connection = ConnectHandler(**parameters)
  File "/home/sunil/.local/lib/python3.8/site-packages/netmiko/ssh_dispatcher.py", line 312, in ConnectHandler
    return ConnectionClass(*args, **kwargs)
  File "/home/sunil/.local/lib/python3.8/site-packages/netmiko/cisco/cisco_ios.py", line 17, in __init__
    return super().__init__(*args, **kwargs)
  File "/home/sunil/.local/lib/python3.8/site-packages/netmiko/base_connection.py", line 346, in __init__
    self._open()
  File "/home/sunil/.local/lib/python3.8/site-packages/netmiko/base_connection.py", line 351, in _open
    self.establish_connection()
  File "/home/sunil/.local/lib/python3.8/site-packages/netmiko/base_connection.py", line 942, in establish_connection
    raise NetmikoTimeoutException(msg)
netmiko.ssh_exception.NetmikoTimeoutException: TCP connection to device failed.

Common causes of this problem are:
1. Incorrect hostname or IP address.
2. Wrong TCP port.
3. Intermediate firewall blocking access.

Device settings: cisco_ios 192.168.127.42:22



2021-04-07 17:29:14,501 - nornir.core.task -    ERROR -      start() - Host 'spine1': task 'VLAN Commands' failed with traceback:
Traceback (most recent call last):
  File "/home/sunil/.local/lib/python3.8/site-packages/netmiko/base_connection.py", line 920, in establish_connection
    self.remote_conn_pre.connect(**ssh_connect_params)
  File "/usr/lib/python3/dist-packages/paramiko/client.py", line 368, in connect
    raise NoValidConnectionsError(errors)
paramiko.ssh_exception.NoValidConnectionsError: [Errno None] Unable to connect to port 22 on 192.168.127.11

During handling of the above exception, another exception occurred:

Traceback (most recent call last):
  File "/home/sunil/.local/lib/python3.8/site-packages/nornir/core/task.py", line 98, in start
    r = self.task(self, **self.params)
  File "/home/sunil/.local/lib/python3.8/site-packages/nornir_netmiko/tasks/netmiko_send_config.py", line 24, in netmiko_send_config
    net_connect = task.host.get_connection(CONNECTION_NAME, task.nornir.config)
  File "/home/sunil/.local/lib/python3.8/site-packages/nornir/core/inventory.py", line 440, in get_connection
    self.open_connection(
  File "/home/sunil/.local/lib/python3.8/site-packages/nornir/core/inventory.py", line 492, in open_connection
    conn_obj.open(
  File "/home/sunil/.local/lib/python3.8/site-packages/nornir_netmiko/connections/netmiko.py", line 59, in open
    connection = ConnectHandler(**parameters)
  File "/home/sunil/.local/lib/python3.8/site-packages/netmiko/ssh_dispatcher.py", line 312, in ConnectHandler
    return ConnectionClass(*args, **kwargs)
  File "/home/sunil/.local/lib/python3.8/site-packages/netmiko/cisco/cisco_nxos_ssh.py", line 12, in __init__
    return super().__init__(*args, **kwargs)
  File "/home/sunil/.local/lib/python3.8/site-packages/netmiko/base_connection.py", line 346, in __init__
    self._open()
  File "/home/sunil/.local/lib/python3.8/site-packages/netmiko/base_connection.py", line 351, in _open
    self.establish_connection()
  File "/home/sunil/.local/lib/python3.8/site-packages/netmiko/base_connection.py", line 942, in establish_connection
    raise NetmikoTimeoutException(msg)
netmiko.ssh_exception.NetmikoTimeoutException: TCP connection to device failed.

Common causes of this problem are:
1. Incorrect hostname or IP address.
2. Wrong TCP port.
3. Intermediate firewall blocking access.

Device settings: cisco_nxos 192.168.127.11:22



2021-04-07 17:29:14,502 - nornir.core.task -    ERROR -      start() - Host 'leaf1': task 'VLAN Commands' failed with traceback:
Traceback (most recent call last):
  File "/home/sunil/.local/lib/python3.8/site-packages/netmiko/base_connection.py", line 920, in establish_connection
    self.remote_conn_pre.connect(**ssh_connect_params)
  File "/usr/lib/python3/dist-packages/paramiko/client.py", line 368, in connect
    raise NoValidConnectionsError(errors)
paramiko.ssh_exception.NoValidConnectionsError: [Errno None] Unable to connect to port 22 on 192.168.127.12

During handling of the above exception, another exception occurred:

Traceback (most recent call last):
  File "/home/sunil/.local/lib/python3.8/site-packages/nornir/core/task.py", line 98, in start
    r = self.task(self, **self.params)
  File "/home/sunil/.local/lib/python3.8/site-packages/nornir_netmiko/tasks/netmiko_send_config.py", line 24, in netmiko_send_config
    net_connect = task.host.get_connection(CONNECTION_NAME, task.nornir.config)
  File "/home/sunil/.local/lib/python3.8/site-packages/nornir/core/inventory.py", line 440, in get_connection
    self.open_connection(
  File "/home/sunil/.local/lib/python3.8/site-packages/nornir/core/inventory.py", line 492, in open_connection
    conn_obj.open(
  File "/home/sunil/.local/lib/python3.8/site-packages/nornir_netmiko/connections/netmiko.py", line 59, in open
    connection = ConnectHandler(**parameters)
  File "/home/sunil/.local/lib/python3.8/site-packages/netmiko/ssh_dispatcher.py", line 312, in ConnectHandler
    return ConnectionClass(*args, **kwargs)
  File "/home/sunil/.local/lib/python3.8/site-packages/netmiko/cisco/cisco_nxos_ssh.py", line 12, in __init__
    return super().__init__(*args, **kwargs)
  File "/home/sunil/.local/lib/python3.8/site-packages/netmiko/base_connection.py", line 346, in __init__
    self._open()
  File "/home/sunil/.local/lib/python3.8/site-packages/netmiko/base_connection.py", line 351, in _open
    self.establish_connection()
  File "/home/sunil/.local/lib/python3.8/site-packages/netmiko/base_connection.py", line 942, in establish_connection
    raise NetmikoTimeoutException(msg)
netmiko.ssh_exception.NetmikoTimeoutException: TCP connection to device failed.

Common causes of this problem are:
1. Incorrect hostname or IP address.
2. Wrong TCP port.
3. Intermediate firewall blocking access.

Device settings: cisco_nxos 192.168.127.12:22



2021-04-07 17:29:14,508 - nornir.core.task -    ERROR -      start() - Host 'leaf1': task 'load_vars' failed with traceback:
Traceback (most recent call last):
  File "/home/sunil/.local/lib/python3.8/site-packages/nornir/core/task.py", line 98, in start
    r = self.task(self, **self.params)
  File "test-150.py", line 86, in load_vars
    basic_configuration(task1)
  File "test-150.py", line 95, in basic_configuration
    task1.run(task=netmiko_send_config, name="VLAN Commands",
  File "/home/sunil/.local/lib/python3.8/site-packages/nornir/core/task.py", line 168, in run
    raise NornirSubTaskError(task=run_task, result=r)
nornir.core.exceptions.NornirSubTaskError: Subtask: VLAN Commands (failed)


2021-04-07 17:29:14,503 - nornir.core.task -    ERROR -      start() - Host 'IOS2': task 'load_vars' failed with traceback:
Traceback (most recent call last):
  File "/home/sunil/.local/lib/python3.8/site-packages/nornir/core/task.py", line 98, in start
    r = self.task(self, **self.params)
  File "test-150.py", line 86, in load_vars
    basic_configuration(task1)
  File "test-150.py", line 95, in basic_configuration
    task1.run(task=netmiko_send_config, name="VLAN Commands",
  File "/home/sunil/.local/lib/python3.8/site-packages/nornir/core/task.py", line 168, in run
    raise NornirSubTaskError(task=run_task, result=r)
nornir.core.exceptions.NornirSubTaskError: Subtask: VLAN Commands (failed)


2021-04-07 17:29:14,510 - nornir.core.task -    ERROR -      start() - Host 'IOS3': task 'VLAN Commands' failed with traceback:
Traceback (most recent call last):
  File "/home/sunil/.local/lib/python3.8/site-packages/netmiko/base_connection.py", line 920, in establish_connection
    self.remote_conn_pre.connect(**ssh_connect_params)
  File "/usr/lib/python3/dist-packages/paramiko/client.py", line 368, in connect
    raise NoValidConnectionsError(errors)
paramiko.ssh_exception.NoValidConnectionsError: [Errno None] Unable to connect to port 22 on 192.168.127.43

During handling of the above exception, another exception occurred:

Traceback (most recent call last):
  File "/home/sunil/.local/lib/python3.8/site-packages/nornir/core/task.py", line 98, in start
    r = self.task(self, **self.params)
  File "/home/sunil/.local/lib/python3.8/site-packages/nornir_netmiko/tasks/netmiko_send_config.py", line 24, in netmiko_send_config
    net_connect = task.host.get_connection(CONNECTION_NAME, task.nornir.config)
  File "/home/sunil/.local/lib/python3.8/site-packages/nornir/core/inventory.py", line 440, in get_connection
    self.open_connection(
  File "/home/sunil/.local/lib/python3.8/site-packages/nornir/core/inventory.py", line 492, in open_connection
    conn_obj.open(
  File "/home/sunil/.local/lib/python3.8/site-packages/nornir_netmiko/connections/netmiko.py", line 59, in open
    connection = ConnectHandler(**parameters)
  File "/home/sunil/.local/lib/python3.8/site-packages/netmiko/ssh_dispatcher.py", line 312, in ConnectHandler
    return ConnectionClass(*args, **kwargs)
  File "/home/sunil/.local/lib/python3.8/site-packages/netmiko/cisco/cisco_ios.py", line 17, in __init__
    return super().__init__(*args, **kwargs)
  File "/home/sunil/.local/lib/python3.8/site-packages/netmiko/base_connection.py", line 346, in __init__
    self._open()
  File "/home/sunil/.local/lib/python3.8/site-packages/netmiko/base_connection.py", line 351, in _open
    self.establish_connection()
  File "/home/sunil/.local/lib/python3.8/site-packages/netmiko/base_connection.py", line 942, in establish_connection
    raise NetmikoTimeoutException(msg)
netmiko.ssh_exception.NetmikoTimeoutException: TCP connection to device failed.

Common causes of this problem are:
1. Incorrect hostname or IP address.
2. Wrong TCP port.
3. Intermediate firewall blocking access.

Device settings: cisco_ios 192.168.127.43:22



2021-04-07 17:29:14,510 - nornir.core.task -    ERROR -      start() - Host 'IOS3': task 'load_vars' failed with traceback:
Traceback (most recent call last):
  File "/home/sunil/.local/lib/python3.8/site-packages/nornir/core/task.py", line 98, in start
    r = self.task(self, **self.params)
  File "test-150.py", line 86, in load_vars
    basic_configuration(task1)
  File "test-150.py", line 95, in basic_configuration
    task1.run(task=netmiko_send_config, name="VLAN Commands",
  File "/home/sunil/.local/lib/python3.8/site-packages/nornir/core/task.py", line 168, in run
    raise NornirSubTaskError(task=run_task, result=r)
nornir.core.exceptions.NornirSubTaskError: Subtask: VLAN Commands (failed)


2021-04-07 17:29:14,508 - nornir.core.task -    ERROR -      start() - Host 'spine1': task 'load_vars' failed with traceback:
Traceback (most recent call last):
  File "/home/sunil/.local/lib/python3.8/site-packages/nornir/core/task.py", line 98, in start
    r = self.task(self, **self.params)
  File "test-150.py", line 86, in load_vars
    basic_configuration(task1)
  File "test-150.py", line 95, in basic_configuration
    task1.run(task=netmiko_send_config, name="VLAN Commands",
  File "/home/sunil/.local/lib/python3.8/site-packages/nornir/core/task.py", line 168, in run
    raise NornirSubTaskError(task=run_task, result=r)
nornir.core.exceptions.NornirSubTaskError: Subtask: VLAN Commands (failed)


2021-04-07 18:06:45,195 -  nornir.core -     INFO -        run() - Running task 'load_vars' with args {} on 5 hosts
2021-04-07 18:06:45,197 - nornir.core.task -    ERROR -      start() - Host 'leaf1': task 'template_file' failed with traceback:
Traceback (most recent call last):
  File "/home/sunil/.local/lib/python3.8/site-packages/nornir/core/task.py", line 98, in start
    r = self.task(self, **self.params)
TypeError: template_file() missing 1 required positional argument: 'path'

2021-04-07 18:06:45,197 - nornir.core.task -    ERROR -      start() - Host 'leaf1': task 'load_vars' failed with traceback:
Traceback (most recent call last):
  File "/home/sunil/.local/lib/python3.8/site-packages/nornir/core/task.py", line 98, in start
    r = self.task(self, **self.params)
  File "ANS-NOR-VAR.py", line 86, in load_vars
    basic_configuration(task1)
  File "ANS-NOR-VAR.py", line 90, in basic_configuration
    r = task1.run(task=template_file, template="L2-VxLAN1.j2")
  File "/home/sunil/.local/lib/python3.8/site-packages/nornir/core/task.py", line 168, in run
    raise NornirSubTaskError(task=run_task, result=r)
nornir.core.exceptions.NornirSubTaskError: Subtask: template_file (failed)


2021-04-07 18:06:45,198 - nornir.core.task -    ERROR -      start() - Host 'spine1': task 'template_file' failed with traceback:
Traceback (most recent call last):
  File "/home/sunil/.local/lib/python3.8/site-packages/nornir/core/task.py", line 98, in start
    r = self.task(self, **self.params)
TypeError: template_file() missing 1 required positional argument: 'path'

2021-04-07 18:06:45,198 - nornir.core.task -    ERROR -      start() - Host 'spine1': task 'load_vars' failed with traceback:
Traceback (most recent call last):
  File "/home/sunil/.local/lib/python3.8/site-packages/nornir/core/task.py", line 98, in start
    r = self.task(self, **self.params)
  File "ANS-NOR-VAR.py", line 86, in load_vars
    basic_configuration(task1)
  File "ANS-NOR-VAR.py", line 90, in basic_configuration
    r = task1.run(task=template_file, template="L2-VxLAN1.j2")
  File "/home/sunil/.local/lib/python3.8/site-packages/nornir/core/task.py", line 168, in run
    raise NornirSubTaskError(task=run_task, result=r)
nornir.core.exceptions.NornirSubTaskError: Subtask: template_file (failed)


2021-04-07 18:06:45,200 - nornir.core.task -    ERROR -      start() - Host 'IOS2': task 'template_file' failed with traceback:
Traceback (most recent call last):
  File "/home/sunil/.local/lib/python3.8/site-packages/nornir/core/task.py", line 98, in start
    r = self.task(self, **self.params)
TypeError: template_file() missing 1 required positional argument: 'path'

2021-04-07 18:06:45,200 - nornir.core.task -    ERROR -      start() - Host 'IOS2': task 'load_vars' failed with traceback:
Traceback (most recent call last):
  File "/home/sunil/.local/lib/python3.8/site-packages/nornir/core/task.py", line 98, in start
    r = self.task(self, **self.params)
  File "ANS-NOR-VAR.py", line 86, in load_vars
    basic_configuration(task1)
  File "ANS-NOR-VAR.py", line 90, in basic_configuration
    r = task1.run(task=template_file, template="L2-VxLAN1.j2")
  File "/home/sunil/.local/lib/python3.8/site-packages/nornir/core/task.py", line 168, in run
    raise NornirSubTaskError(task=run_task, result=r)
nornir.core.exceptions.NornirSubTaskError: Subtask: template_file (failed)


2021-04-07 18:06:45,201 - nornir.core.task -    ERROR -      start() - Host 'IOS3': task 'template_file' failed with traceback:
Traceback (most recent call last):
  File "/home/sunil/.local/lib/python3.8/site-packages/nornir/core/task.py", line 98, in start
    r = self.task(self, **self.params)
TypeError: template_file() missing 1 required positional argument: 'path'

2021-04-07 18:06:45,201 - nornir.core.task -    ERROR -      start() - Host 'IOS3': task 'load_vars' failed with traceback:
Traceback (most recent call last):
  File "/home/sunil/.local/lib/python3.8/site-packages/nornir/core/task.py", line 98, in start
    r = self.task(self, **self.params)
  File "ANS-NOR-VAR.py", line 86, in load_vars
    basic_configuration(task1)
  File "ANS-NOR-VAR.py", line 90, in basic_configuration
    r = task1.run(task=template_file, template="L2-VxLAN1.j2")
  File "/home/sunil/.local/lib/python3.8/site-packages/nornir/core/task.py", line 168, in run
    raise NornirSubTaskError(task=run_task, result=r)
nornir.core.exceptions.NornirSubTaskError: Subtask: template_file (failed)


2021-04-07 18:06:45,202 - nornir.core.task -    ERROR -      start() - Host 'IOS4': task 'template_file' failed with traceback:
Traceback (most recent call last):
  File "/home/sunil/.local/lib/python3.8/site-packages/nornir/core/task.py", line 98, in start
    r = self.task(self, **self.params)
TypeError: template_file() missing 1 required positional argument: 'path'

2021-04-07 18:06:45,202 - nornir.core.task -    ERROR -      start() - Host 'IOS4': task 'load_vars' failed with traceback:
Traceback (most recent call last):
  File "/home/sunil/.local/lib/python3.8/site-packages/nornir/core/task.py", line 98, in start
    r = self.task(self, **self.params)
  File "ANS-NOR-VAR.py", line 86, in load_vars
    basic_configuration(task1)
  File "ANS-NOR-VAR.py", line 90, in basic_configuration
    r = task1.run(task=template_file, template="L2-VxLAN1.j2")
  File "/home/sunil/.local/lib/python3.8/site-packages/nornir/core/task.py", line 168, in run
    raise NornirSubTaskError(task=run_task, result=r)
nornir.core.exceptions.NornirSubTaskError: Subtask: template_file (failed)


2021-04-07 18:58:53,854 -  nornir.core -     INFO -        run() - Running task 'load_vars' with args {} on 5 hosts
2021-04-07 18:58:53,856 - nornir.core.task -    ERROR -      start() - Host 'leaf1': task 'template_file' failed with traceback:
Traceback (most recent call last):
  File "/home/sunil/.local/lib/python3.8/site-packages/nornir/core/task.py", line 98, in start
    r = self.task(self, **self.params)
TypeError: template_file() missing 1 required positional argument: 'path'

2021-04-07 18:58:53,856 - nornir.core.task -    ERROR -      start() - Host 'spine1': task 'template_file' failed with traceback:
Traceback (most recent call last):
  File "/home/sunil/.local/lib/python3.8/site-packages/nornir/core/task.py", line 98, in start
    r = self.task(self, **self.params)
TypeError: template_file() missing 1 required positional argument: 'path'

2021-04-07 18:58:53,857 - nornir.core.task -    ERROR -      start() - Host 'spine1': task 'load_vars' failed with traceback:
Traceback (most recent call last):
  File "/home/sunil/.local/lib/python3.8/site-packages/nornir/core/task.py", line 98, in start
    r = self.task(self, **self.params)
  File "ANS-NOR-VAR.py", line 86, in load_vars
    basic_configuration(task1)
  File "ANS-NOR-VAR.py", line 90, in basic_configuration
    r = task1.run(task=template_file, template="L2-VxLAN1.j2")
  File "/home/sunil/.local/lib/python3.8/site-packages/nornir/core/task.py", line 168, in run
    raise NornirSubTaskError(task=run_task, result=r)
nornir.core.exceptions.NornirSubTaskError: Subtask: template_file (failed)


2021-04-07 18:58:53,858 - nornir.core.task -    ERROR -      start() - Host 'IOS2': task 'template_file' failed with traceback:
Traceback (most recent call last):
  File "/home/sunil/.local/lib/python3.8/site-packages/nornir/core/task.py", line 98, in start
    r = self.task(self, **self.params)
TypeError: template_file() missing 1 required positional argument: 'path'

2021-04-07 18:58:53,858 - nornir.core.task -    ERROR -      start() - Host 'IOS2': task 'load_vars' failed with traceback:
Traceback (most recent call last):
  File "/home/sunil/.local/lib/python3.8/site-packages/nornir/core/task.py", line 98, in start
    r = self.task(self, **self.params)
  File "ANS-NOR-VAR.py", line 86, in load_vars
    basic_configuration(task1)
  File "ANS-NOR-VAR.py", line 90, in basic_configuration
    r = task1.run(task=template_file, template="L2-VxLAN1.j2")
  File "/home/sunil/.local/lib/python3.8/site-packages/nornir/core/task.py", line 168, in run
    raise NornirSubTaskError(task=run_task, result=r)
nornir.core.exceptions.NornirSubTaskError: Subtask: template_file (failed)


2021-04-07 18:58:53,859 - nornir.core.task -    ERROR -      start() - Host 'leaf1': task 'load_vars' failed with traceback:
Traceback (most recent call last):
  File "/home/sunil/.local/lib/python3.8/site-packages/nornir/core/task.py", line 98, in start
    r = self.task(self, **self.params)
  File "ANS-NOR-VAR.py", line 86, in load_vars
    basic_configuration(task1)
  File "ANS-NOR-VAR.py", line 90, in basic_configuration
    r = task1.run(task=template_file, template="L2-VxLAN1.j2")
  File "/home/sunil/.local/lib/python3.8/site-packages/nornir/core/task.py", line 168, in run
    raise NornirSubTaskError(task=run_task, result=r)
nornir.core.exceptions.NornirSubTaskError: Subtask: template_file (failed)


2021-04-07 18:58:53,860 - nornir.core.task -    ERROR -      start() - Host 'IOS3': task 'template_file' failed with traceback:
Traceback (most recent call last):
  File "/home/sunil/.local/lib/python3.8/site-packages/nornir/core/task.py", line 98, in start
    r = self.task(self, **self.params)
TypeError: template_file() missing 1 required positional argument: 'path'

2021-04-07 18:58:53,862 - nornir.core.task -    ERROR -      start() - Host 'IOS3': task 'load_vars' failed with traceback:
Traceback (most recent call last):
  File "/home/sunil/.local/lib/python3.8/site-packages/nornir/core/task.py", line 98, in start
    r = self.task(self, **self.params)
  File "ANS-NOR-VAR.py", line 86, in load_vars
    basic_configuration(task1)
  File "ANS-NOR-VAR.py", line 90, in basic_configuration
    r = task1.run(task=template_file, template="L2-VxLAN1.j2")
  File "/home/sunil/.local/lib/python3.8/site-packages/nornir/core/task.py", line 168, in run
    raise NornirSubTaskError(task=run_task, result=r)
nornir.core.exceptions.NornirSubTaskError: Subtask: template_file (failed)


2021-04-07 18:58:53,861 - nornir.core.task -    ERROR -      start() - Host 'IOS4': task 'template_file' failed with traceback:
Traceback (most recent call last):
  File "/home/sunil/.local/lib/python3.8/site-packages/nornir/core/task.py", line 98, in start
    r = self.task(self, **self.params)
TypeError: template_file() missing 1 required positional argument: 'path'

2021-04-07 18:58:53,862 - nornir.core.task -    ERROR -      start() - Host 'IOS4': task 'load_vars' failed with traceback:
Traceback (most recent call last):
  File "/home/sunil/.local/lib/python3.8/site-packages/nornir/core/task.py", line 98, in start
    r = self.task(self, **self.params)
  File "ANS-NOR-VAR.py", line 86, in load_vars
    basic_configuration(task1)
  File "ANS-NOR-VAR.py", line 90, in basic_configuration
    r = task1.run(task=template_file, template="L2-VxLAN1.j2")
  File "/home/sunil/.local/lib/python3.8/site-packages/nornir/core/task.py", line 168, in run
    raise NornirSubTaskError(task=run_task, result=r)
nornir.core.exceptions.NornirSubTaskError: Subtask: template_file (failed)


2021-04-07 19:19:31,700 -  nornir.core -     INFO -        run() - Running task 'load_vars' with args {} on 5 hosts
2021-04-07 19:19:34,783 - nornir.core.task -    ERROR -      start() - Host 'leaf1': task 'VLAN Commands' failed with traceback:
Traceback (most recent call last):
  File "/home/sunil/.local/lib/python3.8/site-packages/netmiko/base_connection.py", line 920, in establish_connection
    self.remote_conn_pre.connect(**ssh_connect_params)
  File "/usr/lib/python3/dist-packages/paramiko/client.py", line 368, in connect
    raise NoValidConnectionsError(errors)
paramiko.ssh_exception.NoValidConnectionsError: [Errno None] Unable to connect to port 22 on 192.168.127.12

During handling of the above exception, another exception occurred:

Traceback (most recent call last):
  File "/home/sunil/.local/lib/python3.8/site-packages/nornir/core/task.py", line 98, in start
    r = self.task(self, **self.params)
  File "/home/sunil/.local/lib/python3.8/site-packages/nornir_netmiko/tasks/netmiko_send_config.py", line 24, in netmiko_send_config
    net_connect = task.host.get_connection(CONNECTION_NAME, task.nornir.config)
  File "/home/sunil/.local/lib/python3.8/site-packages/nornir/core/inventory.py", line 440, in get_connection
    self.open_connection(
  File "/home/sunil/.local/lib/python3.8/site-packages/nornir/core/inventory.py", line 492, in open_connection
    conn_obj.open(
  File "/home/sunil/.local/lib/python3.8/site-packages/nornir_netmiko/connections/netmiko.py", line 59, in open
    connection = ConnectHandler(**parameters)
  File "/home/sunil/.local/lib/python3.8/site-packages/netmiko/ssh_dispatcher.py", line 312, in ConnectHandler
    return ConnectionClass(*args, **kwargs)
  File "/home/sunil/.local/lib/python3.8/site-packages/netmiko/cisco/cisco_nxos_ssh.py", line 12, in __init__
    return super().__init__(*args, **kwargs)
  File "/home/sunil/.local/lib/python3.8/site-packages/netmiko/base_connection.py", line 346, in __init__
    self._open()
  File "/home/sunil/.local/lib/python3.8/site-packages/netmiko/base_connection.py", line 351, in _open
    self.establish_connection()
  File "/home/sunil/.local/lib/python3.8/site-packages/netmiko/base_connection.py", line 942, in establish_connection
    raise NetmikoTimeoutException(msg)
netmiko.ssh_exception.NetmikoTimeoutException: TCP connection to device failed.

Common causes of this problem are:
1. Incorrect hostname or IP address.
2. Wrong TCP port.
3. Intermediate firewall blocking access.

Device settings: cisco_nxos 192.168.127.12:22



2021-04-07 19:19:34,783 - nornir.core.task -    ERROR -      start() - Host 'leaf1': task 'load_vars' failed with traceback:
Traceback (most recent call last):
  File "/home/sunil/.local/lib/python3.8/site-packages/nornir/core/task.py", line 98, in start
    r = self.task(self, **self.params)
  File "ANS-NOR-VAR.py", line 86, in load_vars
    basic_configuration(task1)
  File "ANS-NOR-VAR.py", line 95, in basic_configuration
    task1.run(task=netmiko_send_config, name="VLAN Commands",
  File "/home/sunil/.local/lib/python3.8/site-packages/nornir/core/task.py", line 168, in run
    raise NornirSubTaskError(task=run_task, result=r)
nornir.core.exceptions.NornirSubTaskError: Subtask: VLAN Commands (failed)


2021-04-07 19:19:34,784 - nornir.core.task -    ERROR -      start() - Host 'IOS2': task 'VLAN Commands' failed with traceback:
Traceback (most recent call last):
  File "/home/sunil/.local/lib/python3.8/site-packages/netmiko/base_connection.py", line 920, in establish_connection
    self.remote_conn_pre.connect(**ssh_connect_params)
  File "/usr/lib/python3/dist-packages/paramiko/client.py", line 368, in connect
    raise NoValidConnectionsError(errors)
paramiko.ssh_exception.NoValidConnectionsError: [Errno None] Unable to connect to port 22 on 192.168.127.42

During handling of the above exception, another exception occurred:

Traceback (most recent call last):
  File "/home/sunil/.local/lib/python3.8/site-packages/nornir/core/task.py", line 98, in start
    r = self.task(self, **self.params)
  File "/home/sunil/.local/lib/python3.8/site-packages/nornir_netmiko/tasks/netmiko_send_config.py", line 24, in netmiko_send_config
    net_connect = task.host.get_connection(CONNECTION_NAME, task.nornir.config)
  File "/home/sunil/.local/lib/python3.8/site-packages/nornir/core/inventory.py", line 440, in get_connection
    self.open_connection(
  File "/home/sunil/.local/lib/python3.8/site-packages/nornir/core/inventory.py", line 492, in open_connection
    conn_obj.open(
  File "/home/sunil/.local/lib/python3.8/site-packages/nornir_netmiko/connections/netmiko.py", line 59, in open
    connection = ConnectHandler(**parameters)
  File "/home/sunil/.local/lib/python3.8/site-packages/netmiko/ssh_dispatcher.py", line 312, in ConnectHandler
    return ConnectionClass(*args, **kwargs)
  File "/home/sunil/.local/lib/python3.8/site-packages/netmiko/cisco/cisco_ios.py", line 17, in __init__
    return super().__init__(*args, **kwargs)
  File "/home/sunil/.local/lib/python3.8/site-packages/netmiko/base_connection.py", line 346, in __init__
    self._open()
  File "/home/sunil/.local/lib/python3.8/site-packages/netmiko/base_connection.py", line 351, in _open
    self.establish_connection()
  File "/home/sunil/.local/lib/python3.8/site-packages/netmiko/base_connection.py", line 942, in establish_connection
    raise NetmikoTimeoutException(msg)
netmiko.ssh_exception.NetmikoTimeoutException: TCP connection to device failed.

Common causes of this problem are:
1. Incorrect hostname or IP address.
2. Wrong TCP port.
3. Intermediate firewall blocking access.

Device settings: cisco_ios 192.168.127.42:22



2021-04-07 19:19:34,784 - nornir.core.task -    ERROR -      start() - Host 'IOS2': task 'load_vars' failed with traceback:
Traceback (most recent call last):
  File "/home/sunil/.local/lib/python3.8/site-packages/nornir/core/task.py", line 98, in start
    r = self.task(self, **self.params)
  File "ANS-NOR-VAR.py", line 86, in load_vars
    basic_configuration(task1)
  File "ANS-NOR-VAR.py", line 95, in basic_configuration
    task1.run(task=netmiko_send_config, name="VLAN Commands",
  File "/home/sunil/.local/lib/python3.8/site-packages/nornir/core/task.py", line 168, in run
    raise NornirSubTaskError(task=run_task, result=r)
nornir.core.exceptions.NornirSubTaskError: Subtask: VLAN Commands (failed)


2021-04-07 19:19:34,784 - nornir.core.task -    ERROR -      start() - Host 'IOS3': task 'VLAN Commands' failed with traceback:
Traceback (most recent call last):
  File "/home/sunil/.local/lib/python3.8/site-packages/netmiko/base_connection.py", line 920, in establish_connection
    self.remote_conn_pre.connect(**ssh_connect_params)
  File "/usr/lib/python3/dist-packages/paramiko/client.py", line 368, in connect
    raise NoValidConnectionsError(errors)
paramiko.ssh_exception.NoValidConnectionsError: [Errno None] Unable to connect to port 22 on 192.168.127.43

During handling of the above exception, another exception occurred:

Traceback (most recent call last):
  File "/home/sunil/.local/lib/python3.8/site-packages/nornir/core/task.py", line 98, in start
    r = self.task(self, **self.params)
  File "/home/sunil/.local/lib/python3.8/site-packages/nornir_netmiko/tasks/netmiko_send_config.py", line 24, in netmiko_send_config
    net_connect = task.host.get_connection(CONNECTION_NAME, task.nornir.config)
  File "/home/sunil/.local/lib/python3.8/site-packages/nornir/core/inventory.py", line 440, in get_connection
    self.open_connection(
  File "/home/sunil/.local/lib/python3.8/site-packages/nornir/core/inventory.py", line 492, in open_connection
    conn_obj.open(
  File "/home/sunil/.local/lib/python3.8/site-packages/nornir_netmiko/connections/netmiko.py", line 59, in open
    connection = ConnectHandler(**parameters)
  File "/home/sunil/.local/lib/python3.8/site-packages/netmiko/ssh_dispatcher.py", line 312, in ConnectHandler
    return ConnectionClass(*args, **kwargs)
  File "/home/sunil/.local/lib/python3.8/site-packages/netmiko/cisco/cisco_ios.py", line 17, in __init__
    return super().__init__(*args, **kwargs)
  File "/home/sunil/.local/lib/python3.8/site-packages/netmiko/base_connection.py", line 346, in __init__
    self._open()
  File "/home/sunil/.local/lib/python3.8/site-packages/netmiko/base_connection.py", line 351, in _open
    self.establish_connection()
  File "/home/sunil/.local/lib/python3.8/site-packages/netmiko/base_connection.py", line 942, in establish_connection
    raise NetmikoTimeoutException(msg)
netmiko.ssh_exception.NetmikoTimeoutException: TCP connection to device failed.

Common causes of this problem are:
1. Incorrect hostname or IP address.
2. Wrong TCP port.
3. Intermediate firewall blocking access.

Device settings: cisco_ios 192.168.127.43:22



2021-04-07 19:19:34,785 - nornir.core.task -    ERROR -      start() - Host 'IOS3': task 'load_vars' failed with traceback:
Traceback (most recent call last):
  File "/home/sunil/.local/lib/python3.8/site-packages/nornir/core/task.py", line 98, in start
    r = self.task(self, **self.params)
  File "ANS-NOR-VAR.py", line 86, in load_vars
    basic_configuration(task1)
  File "ANS-NOR-VAR.py", line 95, in basic_configuration
    task1.run(task=netmiko_send_config, name="VLAN Commands",
  File "/home/sunil/.local/lib/python3.8/site-packages/nornir/core/task.py", line 168, in run
    raise NornirSubTaskError(task=run_task, result=r)
nornir.core.exceptions.NornirSubTaskError: Subtask: VLAN Commands (failed)


2021-04-07 19:19:36,764 - nornir.core.task -    ERROR -      start() - Host 'IOS4': task 'VLAN Commands' failed with traceback:
Traceback (most recent call last):
  File "/home/sunil/.local/lib/python3.8/site-packages/netmiko/base_connection.py", line 920, in establish_connection
    self.remote_conn_pre.connect(**ssh_connect_params)
  File "/usr/lib/python3/dist-packages/paramiko/client.py", line 349, in connect
    retry_on_signal(lambda: sock.connect(addr))
  File "/usr/lib/python3/dist-packages/paramiko/util.py", line 280, in retry_on_signal
    return function()
  File "/usr/lib/python3/dist-packages/paramiko/client.py", line 349, in <lambda>
    retry_on_signal(lambda: sock.connect(addr))
socket.timeout: timed out

During handling of the above exception, another exception occurred:

Traceback (most recent call last):
  File "/home/sunil/.local/lib/python3.8/site-packages/nornir/core/task.py", line 98, in start
    r = self.task(self, **self.params)
  File "/home/sunil/.local/lib/python3.8/site-packages/nornir_netmiko/tasks/netmiko_send_config.py", line 24, in netmiko_send_config
    net_connect = task.host.get_connection(CONNECTION_NAME, task.nornir.config)
  File "/home/sunil/.local/lib/python3.8/site-packages/nornir/core/inventory.py", line 440, in get_connection
    self.open_connection(
  File "/home/sunil/.local/lib/python3.8/site-packages/nornir/core/inventory.py", line 492, in open_connection
    conn_obj.open(
  File "/home/sunil/.local/lib/python3.8/site-packages/nornir_netmiko/connections/netmiko.py", line 59, in open
    connection = ConnectHandler(**parameters)
  File "/home/sunil/.local/lib/python3.8/site-packages/netmiko/ssh_dispatcher.py", line 312, in ConnectHandler
    return ConnectionClass(*args, **kwargs)
  File "/home/sunil/.local/lib/python3.8/site-packages/netmiko/cisco/cisco_ios.py", line 17, in __init__
    return super().__init__(*args, **kwargs)
  File "/home/sunil/.local/lib/python3.8/site-packages/netmiko/base_connection.py", line 346, in __init__
    self._open()
  File "/home/sunil/.local/lib/python3.8/site-packages/netmiko/base_connection.py", line 351, in _open
    self.establish_connection()
  File "/home/sunil/.local/lib/python3.8/site-packages/netmiko/base_connection.py", line 942, in establish_connection
    raise NetmikoTimeoutException(msg)
netmiko.ssh_exception.NetmikoTimeoutException: TCP connection to device failed.

Common causes of this problem are:
1. Incorrect hostname or IP address.
2. Wrong TCP port.
3. Intermediate firewall blocking access.

Device settings: cisco_ios 192.168.127.44:22



2021-04-07 19:19:36,764 - nornir.core.task -    ERROR -      start() - Host 'IOS4': task 'load_vars' failed with traceback:
Traceback (most recent call last):
  File "/home/sunil/.local/lib/python3.8/site-packages/nornir/core/task.py", line 98, in start
    r = self.task(self, **self.params)
  File "ANS-NOR-VAR.py", line 86, in load_vars
    basic_configuration(task1)
  File "ANS-NOR-VAR.py", line 95, in basic_configuration
    task1.run(task=netmiko_send_config, name="VLAN Commands",
  File "/home/sunil/.local/lib/python3.8/site-packages/nornir/core/task.py", line 168, in run
    raise NornirSubTaskError(task=run_task, result=r)
nornir.core.exceptions.NornirSubTaskError: Subtask: VLAN Commands (failed)


2021-04-07 19:26:25,543 -  nornir.core -     INFO -        run() - Running task 'load_vars' with args {} on 5 hosts
2021-04-07 19:26:28,639 - nornir.core.task -    ERROR -      start() - Host 'leaf1': task 'VLAN Commands' failed with traceback:
Traceback (most recent call last):
  File "/home/sunil/.local/lib/python3.8/site-packages/netmiko/base_connection.py", line 920, in establish_connection
    self.remote_conn_pre.connect(**ssh_connect_params)
  File "/usr/lib/python3/dist-packages/paramiko/client.py", line 368, in connect
    raise NoValidConnectionsError(errors)
paramiko.ssh_exception.NoValidConnectionsError: [Errno None] Unable to connect to port 22 on 192.168.127.12

During handling of the above exception, another exception occurred:

Traceback (most recent call last):
  File "/home/sunil/.local/lib/python3.8/site-packages/nornir/core/task.py", line 98, in start
    r = self.task(self, **self.params)
  File "/home/sunil/.local/lib/python3.8/site-packages/nornir_netmiko/tasks/netmiko_send_config.py", line 24, in netmiko_send_config
    net_connect = task.host.get_connection(CONNECTION_NAME, task.nornir.config)
  File "/home/sunil/.local/lib/python3.8/site-packages/nornir/core/inventory.py", line 440, in get_connection
    self.open_connection(
  File "/home/sunil/.local/lib/python3.8/site-packages/nornir/core/inventory.py", line 492, in open_connection
    conn_obj.open(
  File "/home/sunil/.local/lib/python3.8/site-packages/nornir_netmiko/connections/netmiko.py", line 59, in open
    connection = ConnectHandler(**parameters)
  File "/home/sunil/.local/lib/python3.8/site-packages/netmiko/ssh_dispatcher.py", line 312, in ConnectHandler
    return ConnectionClass(*args, **kwargs)
  File "/home/sunil/.local/lib/python3.8/site-packages/netmiko/cisco/cisco_nxos_ssh.py", line 12, in __init__
    return super().__init__(*args, **kwargs)
  File "/home/sunil/.local/lib/python3.8/site-packages/netmiko/base_connection.py", line 346, in __init__
    self._open()
  File "/home/sunil/.local/lib/python3.8/site-packages/netmiko/base_connection.py", line 351, in _open
    self.establish_connection()
  File "/home/sunil/.local/lib/python3.8/site-packages/netmiko/base_connection.py", line 942, in establish_connection
    raise NetmikoTimeoutException(msg)
netmiko.ssh_exception.NetmikoTimeoutException: TCP connection to device failed.

Common causes of this problem are:
1. Incorrect hostname or IP address.
2. Wrong TCP port.
3. Intermediate firewall blocking access.

Device settings: cisco_nxos 192.168.127.12:22



2021-04-07 19:26:28,639 - nornir.core.task -    ERROR -      start() - Host 'IOS3': task 'VLAN Commands' failed with traceback:
Traceback (most recent call last):
  File "/home/sunil/.local/lib/python3.8/site-packages/netmiko/base_connection.py", line 920, in establish_connection
    self.remote_conn_pre.connect(**ssh_connect_params)
  File "/usr/lib/python3/dist-packages/paramiko/client.py", line 368, in connect
    raise NoValidConnectionsError(errors)
paramiko.ssh_exception.NoValidConnectionsError: [Errno None] Unable to connect to port 22 on 192.168.127.43

During handling of the above exception, another exception occurred:

Traceback (most recent call last):
  File "/home/sunil/.local/lib/python3.8/site-packages/nornir/core/task.py", line 98, in start
    r = self.task(self, **self.params)
  File "/home/sunil/.local/lib/python3.8/site-packages/nornir_netmiko/tasks/netmiko_send_config.py", line 24, in netmiko_send_config
    net_connect = task.host.get_connection(CONNECTION_NAME, task.nornir.config)
  File "/home/sunil/.local/lib/python3.8/site-packages/nornir/core/inventory.py", line 440, in get_connection
    self.open_connection(
  File "/home/sunil/.local/lib/python3.8/site-packages/nornir/core/inventory.py", line 492, in open_connection
    conn_obj.open(
  File "/home/sunil/.local/lib/python3.8/site-packages/nornir_netmiko/connections/netmiko.py", line 59, in open
    connection = ConnectHandler(**parameters)
  File "/home/sunil/.local/lib/python3.8/site-packages/netmiko/ssh_dispatcher.py", line 312, in ConnectHandler
    return ConnectionClass(*args, **kwargs)
  File "/home/sunil/.local/lib/python3.8/site-packages/netmiko/cisco/cisco_ios.py", line 17, in __init__
    return super().__init__(*args, **kwargs)
  File "/home/sunil/.local/lib/python3.8/site-packages/netmiko/base_connection.py", line 346, in __init__
    self._open()
  File "/home/sunil/.local/lib/python3.8/site-packages/netmiko/base_connection.py", line 351, in _open
    self.establish_connection()
  File "/home/sunil/.local/lib/python3.8/site-packages/netmiko/base_connection.py", line 942, in establish_connection
    raise NetmikoTimeoutException(msg)
netmiko.ssh_exception.NetmikoTimeoutException: TCP connection to device failed.

Common causes of this problem are:
1. Incorrect hostname or IP address.
2. Wrong TCP port.
3. Intermediate firewall blocking access.

Device settings: cisco_ios 192.168.127.43:22



2021-04-07 19:26:28,640 - nornir.core.task -    ERROR -      start() - Host 'leaf1': task 'load_vars' failed with traceback:
Traceback (most recent call last):
  File "/home/sunil/.local/lib/python3.8/site-packages/nornir/core/task.py", line 98, in start
    r = self.task(self, **self.params)
  File "ANS-NOR-VAR.py", line 86, in load_vars
    basic_configuration(task1)
  File "ANS-NOR-VAR.py", line 95, in basic_configuration
    task1.run(task=netmiko_send_config, name="VLAN Commands",
  File "/home/sunil/.local/lib/python3.8/site-packages/nornir/core/task.py", line 168, in run
    raise NornirSubTaskError(task=run_task, result=r)
nornir.core.exceptions.NornirSubTaskError: Subtask: VLAN Commands (failed)


2021-04-07 19:26:28,640 - nornir.core.task -    ERROR -      start() - Host 'IOS4': task 'VLAN Commands' failed with traceback:
Traceback (most recent call last):
  File "/home/sunil/.local/lib/python3.8/site-packages/netmiko/base_connection.py", line 920, in establish_connection
    self.remote_conn_pre.connect(**ssh_connect_params)
  File "/usr/lib/python3/dist-packages/paramiko/client.py", line 368, in connect
    raise NoValidConnectionsError(errors)
paramiko.ssh_exception.NoValidConnectionsError: [Errno None] Unable to connect to port 22 on 192.168.127.44

During handling of the above exception, another exception occurred:

Traceback (most recent call last):
  File "/home/sunil/.local/lib/python3.8/site-packages/nornir/core/task.py", line 98, in start
    r = self.task(self, **self.params)
  File "/home/sunil/.local/lib/python3.8/site-packages/nornir_netmiko/tasks/netmiko_send_config.py", line 24, in netmiko_send_config
    net_connect = task.host.get_connection(CONNECTION_NAME, task.nornir.config)
  File "/home/sunil/.local/lib/python3.8/site-packages/nornir/core/inventory.py", line 440, in get_connection
    self.open_connection(
  File "/home/sunil/.local/lib/python3.8/site-packages/nornir/core/inventory.py", line 492, in open_connection
    conn_obj.open(
  File "/home/sunil/.local/lib/python3.8/site-packages/nornir_netmiko/connections/netmiko.py", line 59, in open
    connection = ConnectHandler(**parameters)
  File "/home/sunil/.local/lib/python3.8/site-packages/netmiko/ssh_dispatcher.py", line 312, in ConnectHandler
    return ConnectionClass(*args, **kwargs)
  File "/home/sunil/.local/lib/python3.8/site-packages/netmiko/cisco/cisco_ios.py", line 17, in __init__
    return super().__init__(*args, **kwargs)
  File "/home/sunil/.local/lib/python3.8/site-packages/netmiko/base_connection.py", line 346, in __init__
    self._open()
  File "/home/sunil/.local/lib/python3.8/site-packages/netmiko/base_connection.py", line 351, in _open
    self.establish_connection()
  File "/home/sunil/.local/lib/python3.8/site-packages/netmiko/base_connection.py", line 942, in establish_connection
    raise NetmikoTimeoutException(msg)
netmiko.ssh_exception.NetmikoTimeoutException: TCP connection to device failed.

Common causes of this problem are:
1. Incorrect hostname or IP address.
2. Wrong TCP port.
3. Intermediate firewall blocking access.

Device settings: cisco_ios 192.168.127.44:22



2021-04-07 19:26:28,640 - nornir.core.task -    ERROR -      start() - Host 'IOS4': task 'load_vars' failed with traceback:
Traceback (most recent call last):
  File "/home/sunil/.local/lib/python3.8/site-packages/nornir/core/task.py", line 98, in start
    r = self.task(self, **self.params)
  File "ANS-NOR-VAR.py", line 86, in load_vars
    basic_configuration(task1)
  File "ANS-NOR-VAR.py", line 95, in basic_configuration
    task1.run(task=netmiko_send_config, name="VLAN Commands",
  File "/home/sunil/.local/lib/python3.8/site-packages/nornir/core/task.py", line 168, in run
    raise NornirSubTaskError(task=run_task, result=r)
nornir.core.exceptions.NornirSubTaskError: Subtask: VLAN Commands (failed)


2021-04-07 19:26:28,640 - nornir.core.task -    ERROR -      start() - Host 'IOS2': task 'VLAN Commands' failed with traceback:
Traceback (most recent call last):
  File "/home/sunil/.local/lib/python3.8/site-packages/netmiko/base_connection.py", line 920, in establish_connection
    self.remote_conn_pre.connect(**ssh_connect_params)
  File "/usr/lib/python3/dist-packages/paramiko/client.py", line 368, in connect
    raise NoValidConnectionsError(errors)
paramiko.ssh_exception.NoValidConnectionsError: [Errno None] Unable to connect to port 22 on 192.168.127.42

During handling of the above exception, another exception occurred:

Traceback (most recent call last):
  File "/home/sunil/.local/lib/python3.8/site-packages/nornir/core/task.py", line 98, in start
    r = self.task(self, **self.params)
  File "/home/sunil/.local/lib/python3.8/site-packages/nornir_netmiko/tasks/netmiko_send_config.py", line 24, in netmiko_send_config
    net_connect = task.host.get_connection(CONNECTION_NAME, task.nornir.config)
  File "/home/sunil/.local/lib/python3.8/site-packages/nornir/core/inventory.py", line 440, in get_connection
    self.open_connection(
  File "/home/sunil/.local/lib/python3.8/site-packages/nornir/core/inventory.py", line 492, in open_connection
    conn_obj.open(
  File "/home/sunil/.local/lib/python3.8/site-packages/nornir_netmiko/connections/netmiko.py", line 59, in open
    connection = ConnectHandler(**parameters)
  File "/home/sunil/.local/lib/python3.8/site-packages/netmiko/ssh_dispatcher.py", line 312, in ConnectHandler
    return ConnectionClass(*args, **kwargs)
  File "/home/sunil/.local/lib/python3.8/site-packages/netmiko/cisco/cisco_ios.py", line 17, in __init__
    return super().__init__(*args, **kwargs)
  File "/home/sunil/.local/lib/python3.8/site-packages/netmiko/base_connection.py", line 346, in __init__
    self._open()
  File "/home/sunil/.local/lib/python3.8/site-packages/netmiko/base_connection.py", line 351, in _open
    self.establish_connection()
  File "/home/sunil/.local/lib/python3.8/site-packages/netmiko/base_connection.py", line 942, in establish_connection
    raise NetmikoTimeoutException(msg)
netmiko.ssh_exception.NetmikoTimeoutException: TCP connection to device failed.

Common causes of this problem are:
1. Incorrect hostname or IP address.
2. Wrong TCP port.
3. Intermediate firewall blocking access.

Device settings: cisco_ios 192.168.127.42:22



2021-04-07 19:26:28,641 - nornir.core.task -    ERROR -      start() - Host 'IOS2': task 'load_vars' failed with traceback:
Traceback (most recent call last):
  File "/home/sunil/.local/lib/python3.8/site-packages/nornir/core/task.py", line 98, in start
    r = self.task(self, **self.params)
  File "ANS-NOR-VAR.py", line 86, in load_vars
    basic_configuration(task1)
  File "ANS-NOR-VAR.py", line 95, in basic_configuration
    task1.run(task=netmiko_send_config, name="VLAN Commands",
  File "/home/sunil/.local/lib/python3.8/site-packages/nornir/core/task.py", line 168, in run
    raise NornirSubTaskError(task=run_task, result=r)
nornir.core.exceptions.NornirSubTaskError: Subtask: VLAN Commands (failed)


2021-04-07 19:26:28,640 - nornir.core.task -    ERROR -      start() - Host 'IOS3': task 'load_vars' failed with traceback:
Traceback (most recent call last):
  File "/home/sunil/.local/lib/python3.8/site-packages/nornir/core/task.py", line 98, in start
    r = self.task(self, **self.params)
  File "ANS-NOR-VAR.py", line 86, in load_vars
    basic_configuration(task1)
  File "ANS-NOR-VAR.py", line 95, in basic_configuration
    task1.run(task=netmiko_send_config, name="VLAN Commands",
  File "/home/sunil/.local/lib/python3.8/site-packages/nornir/core/task.py", line 168, in run
    raise NornirSubTaskError(task=run_task, result=r)
nornir.core.exceptions.NornirSubTaskError: Subtask: VLAN Commands (failed)


